Traceback (most recent call last):
  File "/root/thesis/masterthesis-implementation-gpt/.venv/lib/python3.12/site-packages/urllib3/connectionpool.py", line 789, in urlopen
    response = self._make_request(
               ^^^^^^^^^^^^^^^^^^^
  File "/root/thesis/masterthesis-implementation-gpt/.venv/lib/python3.12/site-packages/urllib3/connectionpool.py", line 490, in _make_request
    raise new_e
  File "/root/thesis/masterthesis-implementation-gpt/.venv/lib/python3.12/site-packages/urllib3/connectionpool.py", line 466, in _make_request
    self._validate_conn(conn)
  File "/root/thesis/masterthesis-implementation-gpt/.venv/lib/python3.12/site-packages/urllib3/connectionpool.py", line 1095, in _validate_conn
    conn.connect()
  File "/root/thesis/masterthesis-implementation-gpt/.venv/lib/python3.12/site-packages/urllib3/connection.py", line 652, in connect
    sock_and_verified = _ssl_wrap_socket_and_match_hostname(
                        ^^^^^^^^^^^^^^^^^^^^^^^^^^^^^^^^^^^^
  File "/root/thesis/masterthesis-implementation-gpt/.venv/lib/python3.12/site-packages/urllib3/connection.py", line 805, in _ssl_wrap_socket_and_match_hostname
    ssl_sock = ssl_wrap_socket(
               ^^^^^^^^^^^^^^^^
  File "/root/thesis/masterthesis-implementation-gpt/.venv/lib/python3.12/site-packages/urllib3/util/ssl_.py", line 465, in ssl_wrap_socket
    ssl_sock = _ssl_wrap_socket_impl(sock, context, tls_in_tls, server_hostname)
               ^^^^^^^^^^^^^^^^^^^^^^^^^^^^^^^^^^^^^^^^^^^^^^^^^^^^^^^^^^^^^^^^^
  File "/root/thesis/masterthesis-implementation-gpt/.venv/lib/python3.12/site-packages/urllib3/util/ssl_.py", line 509, in _ssl_wrap_socket_impl
    return ssl_context.wrap_socket(sock, server_hostname=server_hostname)
           ^^^^^^^^^^^^^^^^^^^^^^^^^^^^^^^^^^^^^^^^^^^^^^^^^^^^^^^^^^^^^^
  File "/usr/lib/python3.12/ssl.py", line 455, in wrap_socket
    return self.sslsocket_class._create(
           ^^^^^^^^^^^^^^^^^^^^^^^^^^^^^
  File "/usr/lib/python3.12/ssl.py", line 1042, in _create
    self.do_handshake()
  File "/usr/lib/python3.12/ssl.py", line 1320, in do_handshake
    self._sslobj.do_handshake()
ConnectionResetError: [Errno 104] Connection reset by peer

During handling of the above exception, another exception occurred:

Traceback (most recent call last):
  File "/root/thesis/masterthesis-implementation-gpt/.venv/lib/python3.12/site-packages/requests/adapters.py", line 667, in send
    resp = conn.urlopen(
           ^^^^^^^^^^^^^
  File "/root/thesis/masterthesis-implementation-gpt/.venv/lib/python3.12/site-packages/urllib3/connectionpool.py", line 843, in urlopen
    retries = retries.increment(
              ^^^^^^^^^^^^^^^^^^
  File "/root/thesis/masterthesis-implementation-gpt/.venv/lib/python3.12/site-packages/urllib3/util/retry.py", line 474, in increment
    raise reraise(type(error), error, _stacktrace)
          ^^^^^^^^^^^^^^^^^^^^^^^^^^^^^^^^^^^^^^^^
  File "/root/thesis/masterthesis-implementation-gpt/.venv/lib/python3.12/site-packages/urllib3/util/util.py", line 38, in reraise
    raise value.with_traceback(tb)
  File "/root/thesis/masterthesis-implementation-gpt/.venv/lib/python3.12/site-packages/urllib3/connectionpool.py", line 789, in urlopen
    response = self._make_request(
               ^^^^^^^^^^^^^^^^^^^
  File "/root/thesis/masterthesis-implementation-gpt/.venv/lib/python3.12/site-packages/urllib3/connectionpool.py", line 490, in _make_request
    raise new_e
  File "/root/thesis/masterthesis-implementation-gpt/.venv/lib/python3.12/site-packages/urllib3/connectionpool.py", line 466, in _make_request
    self._validate_conn(conn)
  File "/root/thesis/masterthesis-implementation-gpt/.venv/lib/python3.12/site-packages/urllib3/connectionpool.py", line 1095, in _validate_conn
    conn.connect()
  File "/root/thesis/masterthesis-implementation-gpt/.venv/lib/python3.12/site-packages/urllib3/connection.py", line 652, in connect
    sock_and_verified = _ssl_wrap_socket_and_match_hostname(
                        ^^^^^^^^^^^^^^^^^^^^^^^^^^^^^^^^^^^^
  File "/root/thesis/masterthesis-implementation-gpt/.venv/lib/python3.12/site-packages/urllib3/connection.py", line 805, in _ssl_wrap_socket_and_match_hostname
    ssl_sock = ssl_wrap_socket(
               ^^^^^^^^^^^^^^^^
  File "/root/thesis/masterthesis-implementation-gpt/.venv/lib/python3.12/site-packages/urllib3/util/ssl_.py", line 465, in ssl_wrap_socket
    ssl_sock = _ssl_wrap_socket_impl(sock, context, tls_in_tls, server_hostname)
               ^^^^^^^^^^^^^^^^^^^^^^^^^^^^^^^^^^^^^^^^^^^^^^^^^^^^^^^^^^^^^^^^^
  File "/root/thesis/masterthesis-implementation-gpt/.venv/lib/python3.12/site-packages/urllib3/util/ssl_.py", line 509, in _ssl_wrap_socket_impl
    return ssl_context.wrap_socket(sock, server_hostname=server_hostname)
           ^^^^^^^^^^^^^^^^^^^^^^^^^^^^^^^^^^^^^^^^^^^^^^^^^^^^^^^^^^^^^^
  File "/usr/lib/python3.12/ssl.py", line 455, in wrap_socket
    return self.sslsocket_class._create(
           ^^^^^^^^^^^^^^^^^^^^^^^^^^^^^
  File "/usr/lib/python3.12/ssl.py", line 1042, in _create
    self.do_handshake()
  File "/usr/lib/python3.12/ssl.py", line 1320, in do_handshake
    self._sslobj.do_handshake()
urllib3.exceptions.ProtocolError: ('Connection aborted.', ConnectionResetError(104, 'Connection reset by peer'))

During handling of the above exception, another exception occurred:

Traceback (most recent call last):
  File "/root/thesis/masterthesis-implementation-gpt/langchain-agent.py", line 992, in <module>
    first_shot_state = app.invoke(
                       ^^^^^^^^^^^
  File "/root/thesis/masterthesis-implementation-gpt/.venv/lib/python3.12/site-packages/langgraph/pregel/__init__.py", line 1281, in invoke
    for chunk in self.stream(
  File "/root/thesis/masterthesis-implementation-gpt/.venv/lib/python3.12/site-packages/langgraph/pregel/__init__.py", line 966, in stream
    _panic_or_proceed(done, inflight, loop.step)
  File "/root/thesis/masterthesis-implementation-gpt/.venv/lib/python3.12/site-packages/langgraph/pregel/__init__.py", line 1367, in _panic_or_proceed
    raise exc
  File "/root/thesis/masterthesis-implementation-gpt/.venv/lib/python3.12/site-packages/langgraph/pregel/executor.py", line 60, in done
    task.result()
  File "/usr/lib/python3.12/concurrent/futures/_base.py", line 449, in result
    return self.__get_result()
           ^^^^^^^^^^^^^^^^^^^
  File "/usr/lib/python3.12/concurrent/futures/_base.py", line 401, in __get_result
    raise self._exception
  File "/usr/lib/python3.12/concurrent/futures/thread.py", line 58, in run
    result = self.fn(*self.args, **self.kwargs)
             ^^^^^^^^^^^^^^^^^^^^^^^^^^^^^^^^^^
  File "/root/thesis/masterthesis-implementation-gpt/.venv/lib/python3.12/site-packages/langgraph/pregel/retry.py", line 25, in run_with_retry
    task.proc.invoke(task.input, task.config)
  File "/root/thesis/masterthesis-implementation-gpt/.venv/lib/python3.12/site-packages/langchain_core/runnables/base.py", line 2873, in invoke
    input = step.invoke(input, config, **kwargs)
            ^^^^^^^^^^^^^^^^^^^^^^^^^^^^^^^^^^^^
  File "/root/thesis/masterthesis-implementation-gpt/.venv/lib/python3.12/site-packages/langgraph/utils.py", line 102, in invoke
    ret = context.run(self.func, input, **kwargs)
          ^^^^^^^^^^^^^^^^^^^^^^^^^^^^^^^^^^^^^^^
  File "/root/thesis/masterthesis-implementation-gpt/langchain-agent.py", line 943, in call_model
    response = llm_with_tools.invoke(messages)
               ^^^^^^^^^^^^^^^^^^^^^^^^^^^^^^^
  File "/root/thesis/masterthesis-implementation-gpt/.venv/lib/python3.12/site-packages/langchain_core/runnables/base.py", line 5060, in invoke
    return self.bound.invoke(
           ^^^^^^^^^^^^^^^^^^
  File "/root/thesis/masterthesis-implementation-gpt/.venv/lib/python3.12/site-packages/langchain_core/language_models/chat_models.py", line 274, in invoke
    self.generate_prompt(
  File "/root/thesis/masterthesis-implementation-gpt/.venv/lib/python3.12/site-packages/langchain_core/language_models/chat_models.py", line 714, in generate_prompt
    return self.generate(prompt_messages, stop=stop, callbacks=callbacks, **kwargs)
           ^^^^^^^^^^^^^^^^^^^^^^^^^^^^^^^^^^^^^^^^^^^^^^^^^^^^^^^^^^^^^^^^^^^^^^^^
  File "/root/thesis/masterthesis-implementation-gpt/.venv/lib/python3.12/site-packages/langchain_core/language_models/chat_models.py", line 571, in generate
    raise e
  File "/root/thesis/masterthesis-implementation-gpt/.venv/lib/python3.12/site-packages/langchain_core/language_models/chat_models.py", line 561, in generate
    self._generate_with_cache(
  File "/root/thesis/masterthesis-implementation-gpt/.venv/lib/python3.12/site-packages/langchain_core/language_models/chat_models.py", line 793, in _generate_with_cache
    result = self._generate(
             ^^^^^^^^^^^^^^^
  File "/root/thesis/masterthesis-implementation-gpt/.venv/lib/python3.12/site-packages/langchain_nvidia_ai_endpoints/chat_models.py", line 289, in _generate
    response = self._client.get_req(payload=payload)
               ^^^^^^^^^^^^^^^^^^^^^^^^^^^^^^^^^^^^^
  File "/root/thesis/masterthesis-implementation-gpt/.venv/lib/python3.12/site-packages/langchain_nvidia_ai_endpoints/_common.py", line 460, in get_req
    response, session = self._post(self.infer_url, payload)
                        ^^^^^^^^^^^^^^^^^^^^^^^^^^^^^^^^^^^
  File "/root/thesis/masterthesis-implementation-gpt/.venv/lib/python3.12/site-packages/langchain_nvidia_ai_endpoints/_common.py", line 354, in _post
    self.last_response = response = session.post(
                                    ^^^^^^^^^^^^^
  File "/root/thesis/masterthesis-implementation-gpt/.venv/lib/python3.12/site-packages/requests/sessions.py", line 637, in post
    return self.request("POST", url, data=data, json=json, **kwargs)
           ^^^^^^^^^^^^^^^^^^^^^^^^^^^^^^^^^^^^^^^^^^^^^^^^^^^^^^^^^
  File "/root/thesis/masterthesis-implementation-gpt/.venv/lib/python3.12/site-packages/requests/sessions.py", line 589, in request
    resp = self.send(prep, **send_kwargs)
           ^^^^^^^^^^^^^^^^^^^^^^^^^^^^^^
  File "/root/thesis/masterthesis-implementation-gpt/.venv/lib/python3.12/site-packages/requests/sessions.py", line 703, in send
    r = adapter.send(request, **kwargs)
        ^^^^^^^^^^^^^^^^^^^^^^^^^^^^^^^
  File "/root/thesis/masterthesis-implementation-gpt/.venv/lib/python3.12/site-packages/requests/adapters.py", line 682, in send
    raise ConnectionError(err, request=request)
requests.exceptions.ConnectionError: ('Connection aborted.', ConnectionResetError(104, 'Connection reset by peer'))
